
####2018/02/19 16:59:17####
Traceback (most recent call last):
  File "/home/kiritan/.pyenv/versions/3.6.4/lib/python3.6/site-packages/urllib3/response.py", line 543, in _update_chunk_length
    self.chunk_left = int(line, 16)
ValueError: invalid literal for int() with base 16: b''

During handling of the above exception, another exception occurred:

Traceback (most recent call last):
  File "/home/kiritan/.pyenv/versions/3.6.4/lib/python3.6/site-packages/urllib3/response.py", line 302, in _error_catcher
    yield
  File "/home/kiritan/.pyenv/versions/3.6.4/lib/python3.6/site-packages/urllib3/response.py", line 598, in read_chunked
    self._update_chunk_length()
  File "/home/kiritan/.pyenv/versions/3.6.4/lib/python3.6/site-packages/urllib3/response.py", line 547, in _update_chunk_length
    raise httplib.IncompleteRead(line)
http.client.IncompleteRead: IncompleteRead(0 bytes read)

During handling of the above exception, another exception occurred:

Traceback (most recent call last):
  File "/home/kiritan/.pyenv/versions/3.6.4/lib/python3.6/site-packages/requests/models.py", line 745, in generate
    for chunk in self.raw.stream(chunk_size, decode_content=True):
  File "/home/kiritan/.pyenv/versions/3.6.4/lib/python3.6/site-packages/urllib3/response.py", line 432, in stream
    for line in self.read_chunked(amt, decode_content=decode_content):
  File "/home/kiritan/.pyenv/versions/3.6.4/lib/python3.6/site-packages/urllib3/response.py", line 626, in read_chunked
    self._original_response.close()
  File "/home/kiritan/.pyenv/versions/3.6.4/lib/python3.6/contextlib.py", line 99, in __exit__
    self.gen.throw(type, value, traceback)
  File "/home/kiritan/.pyenv/versions/3.6.4/lib/python3.6/site-packages/urllib3/response.py", line 320, in _error_catcher
    raise ProtocolError('Connection broken: %r' % e, e)
urllib3.exceptions.ProtocolError: ('Connection broken: IncompleteRead(0 bytes read)', IncompleteRead(0 bytes read))

During handling of the above exception, another exception occurred:

Traceback (most recent call last):
  File "kiri_main.py", line 906, in t_user
    mastodon.stream_user(men_toot())
  File "<decorator-gen-65>", line 2, in stream_user
  File "/home/kiritan/.pyenv/versions/3.6.4/lib/python3.6/site-packages/mastodon/Mastodon.py", line 57, in wrapper
    return function(self, *args, **kwargs)
  File "/home/kiritan/.pyenv/versions/3.6.4/lib/python3.6/site-packages/mastodon/Mastodon.py", line 1391, in stream_user
    return self.__stream('/api/v1/streaming/user', listener, async=async)
  File "/home/kiritan/.pyenv/versions/3.6.4/lib/python3.6/site-packages/mastodon/Mastodon.py", line 1732, in __stream
    listener.handle_stream(r)
  File "/home/kiritan/.pyenv/versions/3.6.4/lib/python3.6/site-packages/mastodon/streaming.py", line 46, in handle_stream
    for chunk in response.iter_content(chunk_size = 1):
  File "/home/kiritan/.pyenv/versions/3.6.4/lib/python3.6/site-packages/requests/models.py", line 748, in generate
    raise ChunkedEncodingError(e)
requests.exceptions.ChunkedEncodingError: ('Connection broken: IncompleteRead(0 bytes read)', IncompleteRead(0 bytes read))

####2018/02/19 16:59:17####
Traceback (most recent call last):
  File "/home/kiritan/.pyenv/versions/3.6.4/lib/python3.6/site-packages/urllib3/response.py", line 543, in _update_chunk_length
    self.chunk_left = int(line, 16)
ValueError: invalid literal for int() with base 16: b''

During handling of the above exception, another exception occurred:

Traceback (most recent call last):
  File "/home/kiritan/.pyenv/versions/3.6.4/lib/python3.6/site-packages/urllib3/response.py", line 302, in _error_catcher
    yield
  File "/home/kiritan/.pyenv/versions/3.6.4/lib/python3.6/site-packages/urllib3/response.py", line 598, in read_chunked
    self._update_chunk_length()
  File "/home/kiritan/.pyenv/versions/3.6.4/lib/python3.6/site-packages/urllib3/response.py", line 547, in _update_chunk_length
    raise httplib.IncompleteRead(line)
http.client.IncompleteRead: IncompleteRead(0 bytes read)

During handling of the above exception, another exception occurred:

Traceback (most recent call last):
  File "/home/kiritan/.pyenv/versions/3.6.4/lib/python3.6/site-packages/requests/models.py", line 745, in generate
    for chunk in self.raw.stream(chunk_size, decode_content=True):
  File "/home/kiritan/.pyenv/versions/3.6.4/lib/python3.6/site-packages/urllib3/response.py", line 432, in stream
    for line in self.read_chunked(amt, decode_content=decode_content):
  File "/home/kiritan/.pyenv/versions/3.6.4/lib/python3.6/site-packages/urllib3/response.py", line 626, in read_chunked
    self._original_response.close()
  File "/home/kiritan/.pyenv/versions/3.6.4/lib/python3.6/contextlib.py", line 99, in __exit__
    self.gen.throw(type, value, traceback)
  File "/home/kiritan/.pyenv/versions/3.6.4/lib/python3.6/site-packages/urllib3/response.py", line 320, in _error_catcher
    raise ProtocolError('Connection broken: %r' % e, e)
urllib3.exceptions.ProtocolError: ('Connection broken: IncompleteRead(0 bytes read)', IncompleteRead(0 bytes read))

During handling of the above exception, another exception occurred:

Traceback (most recent call last):
  File "kiri_main.py", line 898, in t_local
    mastodon.stream_local(res_toot())
  File "<decorator-gen-67>", line 2, in stream_local
  File "/home/kiritan/.pyenv/versions/3.6.4/lib/python3.6/site-packages/mastodon/Mastodon.py", line 57, in wrapper
    return function(self, *args, **kwargs)
  File "/home/kiritan/.pyenv/versions/3.6.4/lib/python3.6/site-packages/mastodon/Mastodon.py", line 1405, in stream_local
    return self.__stream('/api/v1/streaming/public/local', listener, async=async)
  File "/home/kiritan/.pyenv/versions/3.6.4/lib/python3.6/site-packages/mastodon/Mastodon.py", line 1732, in __stream
    listener.handle_stream(r)
  File "/home/kiritan/.pyenv/versions/3.6.4/lib/python3.6/site-packages/mastodon/streaming.py", line 46, in handle_stream
    for chunk in response.iter_content(chunk_size = 1):
  File "/home/kiritan/.pyenv/versions/3.6.4/lib/python3.6/site-packages/requests/models.py", line 748, in generate
    raise ChunkedEncodingError(e)
requests.exceptions.ChunkedEncodingError: ('Connection broken: IncompleteRead(0 bytes read)', IncompleteRead(0 bytes read))

####2018/02/19 18:01:00####
Traceback (most recent call last):
  File "/home/kiritan/.pyenv/versions/3.6.4/lib/python3.6/site-packages/urllib3/response.py", line 543, in _update_chunk_length
    self.chunk_left = int(line, 16)
ValueError: invalid literal for int() with base 16: b''

During handling of the above exception, another exception occurred:

Traceback (most recent call last):
  File "/home/kiritan/.pyenv/versions/3.6.4/lib/python3.6/site-packages/urllib3/response.py", line 302, in _error_catcher
    yield
  File "/home/kiritan/.pyenv/versions/3.6.4/lib/python3.6/site-packages/urllib3/response.py", line 598, in read_chunked
    self._update_chunk_length()
  File "/home/kiritan/.pyenv/versions/3.6.4/lib/python3.6/site-packages/urllib3/response.py", line 547, in _update_chunk_length
    raise httplib.IncompleteRead(line)
http.client.IncompleteRead: IncompleteRead(0 bytes read)

During handling of the above exception, another exception occurred:

Traceback (most recent call last):
  File "/home/kiritan/.pyenv/versions/3.6.4/lib/python3.6/site-packages/requests/models.py", line 745, in generate
    for chunk in self.raw.stream(chunk_size, decode_content=True):
  File "/home/kiritan/.pyenv/versions/3.6.4/lib/python3.6/site-packages/urllib3/response.py", line 432, in stream
    for line in self.read_chunked(amt, decode_content=decode_content):
  File "/home/kiritan/.pyenv/versions/3.6.4/lib/python3.6/site-packages/urllib3/response.py", line 626, in read_chunked
    self._original_response.close()
  File "/home/kiritan/.pyenv/versions/3.6.4/lib/python3.6/contextlib.py", line 99, in __exit__
    self.gen.throw(type, value, traceback)
  File "/home/kiritan/.pyenv/versions/3.6.4/lib/python3.6/site-packages/urllib3/response.py", line 320, in _error_catcher
    raise ProtocolError('Connection broken: %r' % e, e)
urllib3.exceptions.ProtocolError: ('Connection broken: IncompleteRead(0 bytes read)', IncompleteRead(0 bytes read))

During handling of the above exception, another exception occurred:

Traceback (most recent call last):
  File "kiri_main.py", line 906, in t_user
    mastodon.stream_user(men_toot())
  File "<decorator-gen-65>", line 2, in stream_user
  File "/home/kiritan/.pyenv/versions/3.6.4/lib/python3.6/site-packages/mastodon/Mastodon.py", line 57, in wrapper
    return function(self, *args, **kwargs)
  File "/home/kiritan/.pyenv/versions/3.6.4/lib/python3.6/site-packages/mastodon/Mastodon.py", line 1391, in stream_user
    return self.__stream('/api/v1/streaming/user', listener, async=async)
  File "/home/kiritan/.pyenv/versions/3.6.4/lib/python3.6/site-packages/mastodon/Mastodon.py", line 1732, in __stream
    listener.handle_stream(r)
  File "/home/kiritan/.pyenv/versions/3.6.4/lib/python3.6/site-packages/mastodon/streaming.py", line 46, in handle_stream
    for chunk in response.iter_content(chunk_size = 1):
  File "/home/kiritan/.pyenv/versions/3.6.4/lib/python3.6/site-packages/requests/models.py", line 748, in generate
    raise ChunkedEncodingError(e)
requests.exceptions.ChunkedEncodingError: ('Connection broken: IncompleteRead(0 bytes read)', IncompleteRead(0 bytes read))

During handling of the above exception, another exception occurred:

Traceback (most recent call last):
  File "/home/kiritan/.pyenv/versions/3.6.4/lib/python3.6/site-packages/urllib3/response.py", line 543, in _update_chunk_length
    self.chunk_left = int(line, 16)
ValueError: invalid literal for int() with base 16: b''

During handling of the above exception, another exception occurred:

Traceback (most recent call last):
  File "/home/kiritan/.pyenv/versions/3.6.4/lib/python3.6/site-packages/urllib3/response.py", line 302, in _error_catcher
    yield
  File "/home/kiritan/.pyenv/versions/3.6.4/lib/python3.6/site-packages/urllib3/response.py", line 598, in read_chunked
    self._update_chunk_length()
  File "/home/kiritan/.pyenv/versions/3.6.4/lib/python3.6/site-packages/urllib3/response.py", line 547, in _update_chunk_length
    raise httplib.IncompleteRead(line)
http.client.IncompleteRead: IncompleteRead(0 bytes read)

During handling of the above exception, another exception occurred:

Traceback (most recent call last):
  File "/home/kiritan/.pyenv/versions/3.6.4/lib/python3.6/site-packages/requests/models.py", line 745, in generate
    for chunk in self.raw.stream(chunk_size, decode_content=True):
  File "/home/kiritan/.pyenv/versions/3.6.4/lib/python3.6/site-packages/urllib3/response.py", line 432, in stream
    for line in self.read_chunked(amt, decode_content=decode_content):
  File "/home/kiritan/.pyenv/versions/3.6.4/lib/python3.6/site-packages/urllib3/response.py", line 626, in read_chunked
    self._original_response.close()
  File "/home/kiritan/.pyenv/versions/3.6.4/lib/python3.6/contextlib.py", line 99, in __exit__
    self.gen.throw(type, value, traceback)
  File "/home/kiritan/.pyenv/versions/3.6.4/lib/python3.6/site-packages/urllib3/response.py", line 320, in _error_catcher
    raise ProtocolError('Connection broken: %r' % e, e)
urllib3.exceptions.ProtocolError: ('Connection broken: IncompleteRead(0 bytes read)', IncompleteRead(0 bytes read))

During handling of the above exception, another exception occurred:

Traceback (most recent call last):
  File "kiri_main.py", line 906, in t_user
    mastodon.stream_user(men_toot())
  File "<decorator-gen-65>", line 2, in stream_user
  File "/home/kiritan/.pyenv/versions/3.6.4/lib/python3.6/site-packages/mastodon/Mastodon.py", line 57, in wrapper
    return function(self, *args, **kwargs)
  File "/home/kiritan/.pyenv/versions/3.6.4/lib/python3.6/site-packages/mastodon/Mastodon.py", line 1391, in stream_user
    return self.__stream('/api/v1/streaming/user', listener, async=async)
  File "/home/kiritan/.pyenv/versions/3.6.4/lib/python3.6/site-packages/mastodon/Mastodon.py", line 1732, in __stream
    listener.handle_stream(r)
  File "/home/kiritan/.pyenv/versions/3.6.4/lib/python3.6/site-packages/mastodon/streaming.py", line 46, in handle_stream
    for chunk in response.iter_content(chunk_size = 1):
  File "/home/kiritan/.pyenv/versions/3.6.4/lib/python3.6/site-packages/requests/models.py", line 748, in generate
    raise ChunkedEncodingError(e)
requests.exceptions.ChunkedEncodingError: ('Connection broken: IncompleteRead(0 bytes read)', IncompleteRead(0 bytes read))

####2018/02/19 18:01:00####
Traceback (most recent call last):
  File "/home/kiritan/.pyenv/versions/3.6.4/lib/python3.6/site-packages/urllib3/response.py", line 543, in _update_chunk_length
    self.chunk_left = int(line, 16)
ValueError: invalid literal for int() with base 16: b''

During handling of the above exception, another exception occurred:

Traceback (most recent call last):
  File "/home/kiritan/.pyenv/versions/3.6.4/lib/python3.6/site-packages/urllib3/response.py", line 302, in _error_catcher
    yield
  File "/home/kiritan/.pyenv/versions/3.6.4/lib/python3.6/site-packages/urllib3/response.py", line 598, in read_chunked
    self._update_chunk_length()
  File "/home/kiritan/.pyenv/versions/3.6.4/lib/python3.6/site-packages/urllib3/response.py", line 547, in _update_chunk_length
    raise httplib.IncompleteRead(line)
http.client.IncompleteRead: IncompleteRead(0 bytes read)

During handling of the above exception, another exception occurred:

Traceback (most recent call last):
  File "/home/kiritan/.pyenv/versions/3.6.4/lib/python3.6/site-packages/requests/models.py", line 745, in generate
    for chunk in self.raw.stream(chunk_size, decode_content=True):
  File "/home/kiritan/.pyenv/versions/3.6.4/lib/python3.6/site-packages/urllib3/response.py", line 432, in stream
    for line in self.read_chunked(amt, decode_content=decode_content):
  File "/home/kiritan/.pyenv/versions/3.6.4/lib/python3.6/site-packages/urllib3/response.py", line 626, in read_chunked
    self._original_response.close()
  File "/home/kiritan/.pyenv/versions/3.6.4/lib/python3.6/contextlib.py", line 99, in __exit__
    self.gen.throw(type, value, traceback)
  File "/home/kiritan/.pyenv/versions/3.6.4/lib/python3.6/site-packages/urllib3/response.py", line 320, in _error_catcher
    raise ProtocolError('Connection broken: %r' % e, e)
urllib3.exceptions.ProtocolError: ('Connection broken: IncompleteRead(0 bytes read)', IncompleteRead(0 bytes read))

During handling of the above exception, another exception occurred:

Traceback (most recent call last):
  File "kiri_main.py", line 898, in t_local
    mastodon.stream_local(res_toot())
  File "<decorator-gen-67>", line 2, in stream_local
  File "/home/kiritan/.pyenv/versions/3.6.4/lib/python3.6/site-packages/mastodon/Mastodon.py", line 57, in wrapper
    return function(self, *args, **kwargs)
  File "/home/kiritan/.pyenv/versions/3.6.4/lib/python3.6/site-packages/mastodon/Mastodon.py", line 1405, in stream_local
    return self.__stream('/api/v1/streaming/public/local', listener, async=async)
  File "/home/kiritan/.pyenv/versions/3.6.4/lib/python3.6/site-packages/mastodon/Mastodon.py", line 1732, in __stream
    listener.handle_stream(r)
  File "/home/kiritan/.pyenv/versions/3.6.4/lib/python3.6/site-packages/mastodon/streaming.py", line 46, in handle_stream
    for chunk in response.iter_content(chunk_size = 1):
  File "/home/kiritan/.pyenv/versions/3.6.4/lib/python3.6/site-packages/requests/models.py", line 748, in generate
    raise ChunkedEncodingError(e)
requests.exceptions.ChunkedEncodingError: ('Connection broken: IncompleteRead(0 bytes read)', IncompleteRead(0 bytes read))

During handling of the above exception, another exception occurred:

Traceback (most recent call last):
  File "/home/kiritan/.pyenv/versions/3.6.4/lib/python3.6/site-packages/urllib3/response.py", line 543, in _update_chunk_length
    self.chunk_left = int(line, 16)
ValueError: invalid literal for int() with base 16: b''

During handling of the above exception, another exception occurred:

Traceback (most recent call last):
  File "/home/kiritan/.pyenv/versions/3.6.4/lib/python3.6/site-packages/urllib3/response.py", line 302, in _error_catcher
    yield
  File "/home/kiritan/.pyenv/versions/3.6.4/lib/python3.6/site-packages/urllib3/response.py", line 598, in read_chunked
    self._update_chunk_length()
  File "/home/kiritan/.pyenv/versions/3.6.4/lib/python3.6/site-packages/urllib3/response.py", line 547, in _update_chunk_length
    raise httplib.IncompleteRead(line)
http.client.IncompleteRead: IncompleteRead(0 bytes read)

During handling of the above exception, another exception occurred:

Traceback (most recent call last):
  File "/home/kiritan/.pyenv/versions/3.6.4/lib/python3.6/site-packages/requests/models.py", line 745, in generate
    for chunk in self.raw.stream(chunk_size, decode_content=True):
  File "/home/kiritan/.pyenv/versions/3.6.4/lib/python3.6/site-packages/urllib3/response.py", line 432, in stream
    for line in self.read_chunked(amt, decode_content=decode_content):
  File "/home/kiritan/.pyenv/versions/3.6.4/lib/python3.6/site-packages/urllib3/response.py", line 626, in read_chunked
    self._original_response.close()
  File "/home/kiritan/.pyenv/versions/3.6.4/lib/python3.6/contextlib.py", line 99, in __exit__
    self.gen.throw(type, value, traceback)
  File "/home/kiritan/.pyenv/versions/3.6.4/lib/python3.6/site-packages/urllib3/response.py", line 320, in _error_catcher
    raise ProtocolError('Connection broken: %r' % e, e)
urllib3.exceptions.ProtocolError: ('Connection broken: IncompleteRead(0 bytes read)', IncompleteRead(0 bytes read))

During handling of the above exception, another exception occurred:

Traceback (most recent call last):
  File "kiri_main.py", line 898, in t_local
    mastodon.stream_local(res_toot())
  File "<decorator-gen-67>", line 2, in stream_local
  File "/home/kiritan/.pyenv/versions/3.6.4/lib/python3.6/site-packages/mastodon/Mastodon.py", line 57, in wrapper
    return function(self, *args, **kwargs)
  File "/home/kiritan/.pyenv/versions/3.6.4/lib/python3.6/site-packages/mastodon/Mastodon.py", line 1405, in stream_local
    return self.__stream('/api/v1/streaming/public/local', listener, async=async)
  File "/home/kiritan/.pyenv/versions/3.6.4/lib/python3.6/site-packages/mastodon/Mastodon.py", line 1732, in __stream
    listener.handle_stream(r)
  File "/home/kiritan/.pyenv/versions/3.6.4/lib/python3.6/site-packages/mastodon/streaming.py", line 46, in handle_stream
    for chunk in response.iter_content(chunk_size = 1):
  File "/home/kiritan/.pyenv/versions/3.6.4/lib/python3.6/site-packages/requests/models.py", line 748, in generate
    raise ChunkedEncodingError(e)
requests.exceptions.ChunkedEncodingError: ('Connection broken: IncompleteRead(0 bytes read)', IncompleteRead(0 bytes read))

####2018/02/19 20:00:45####
Traceback (most recent call last):
  File "kiri_main.py", line 594, in th_worker
    filename = download(media["url"] , "media")
  File "kiri_main.py", line 405, in download
    with open(ret_path, 'wb') as file:
FileNotFoundError: [Errno 2] No such file or directory: 'media/11862740af81fcab.jpeg'

####2018/02/19 20:02:58####
Traceback (most recent call last):
  File "kiri_main.py", line 594, in th_worker
    filename = download(media["url"] , "media")
  File "kiri_main.py", line 405, in download
    with open(ret_path, 'wb') as file:
FileNotFoundError: [Errno 2] No such file or directory: 'media/f630d41a46d6ab88.jpeg'

####2018/02/19 20:06:41####
Traceback (most recent call last):
  File "kiri_main.py", line 594, in th_worker
    filename = download(media["url"] , "media")
  File "kiri_main.py", line 405, in download
    with open(ret_path, 'wb') as file:
FileNotFoundError: [Errno 2] No such file or directory: 'media/2a34676b896edf49.jpeg'

####2018/02/20 22:57:09####
Traceback (most recent call last):
  File "/home/kiritan/.pyenv/versions/3.6.4/lib/python3.6/site-packages/urllib3/response.py", line 543, in _update_chunk_length
    self.chunk_left = int(line, 16)
ValueError: invalid literal for int() with base 16: b''

During handling of the above exception, another exception occurred:

Traceback (most recent call last):
  File "/home/kiritan/.pyenv/versions/3.6.4/lib/python3.6/site-packages/urllib3/response.py", line 302, in _error_catcher
    yield
  File "/home/kiritan/.pyenv/versions/3.6.4/lib/python3.6/site-packages/urllib3/response.py", line 598, in read_chunked
    self._update_chunk_length()
  File "/home/kiritan/.pyenv/versions/3.6.4/lib/python3.6/site-packages/urllib3/response.py", line 547, in _update_chunk_length
    raise httplib.IncompleteRead(line)
http.client.IncompleteRead: IncompleteRead(0 bytes read)

During handling of the above exception, another exception occurred:

Traceback (most recent call last):
  File "/home/kiritan/.pyenv/versions/3.6.4/lib/python3.6/site-packages/requests/models.py", line 745, in generate
    for chunk in self.raw.stream(chunk_size, decode_content=True):
  File "/home/kiritan/.pyenv/versions/3.6.4/lib/python3.6/site-packages/urllib3/response.py", line 432, in stream
    for line in self.read_chunked(amt, decode_content=decode_content):
  File "/home/kiritan/.pyenv/versions/3.6.4/lib/python3.6/site-packages/urllib3/response.py", line 626, in read_chunked
    self._original_response.close()
  File "/home/kiritan/.pyenv/versions/3.6.4/lib/python3.6/contextlib.py", line 99, in __exit__
    self.gen.throw(type, value, traceback)
  File "/home/kiritan/.pyenv/versions/3.6.4/lib/python3.6/site-packages/urllib3/response.py", line 320, in _error_catcher
    raise ProtocolError('Connection broken: %r' % e, e)
urllib3.exceptions.ProtocolError: ('Connection broken: IncompleteRead(0 bytes read)', IncompleteRead(0 bytes read))

During handling of the above exception, another exception occurred:

Traceback (most recent call last):
  File "kiri_main.py", line 902, in t_local
    mastodon.stream_public(res_toot())
  File "<decorator-gen-66>", line 2, in stream_public
  File "/home/kiritan/.pyenv/versions/3.6.4/lib/python3.6/site-packages/mastodon/Mastodon.py", line 57, in wrapper
    return function(self, *args, **kwargs)
  File "/home/kiritan/.pyenv/versions/3.6.4/lib/python3.6/site-packages/mastodon/Mastodon.py", line 1398, in stream_public
    return self.__stream('/api/v1/streaming/public', listener, async=async)
  File "/home/kiritan/.pyenv/versions/3.6.4/lib/python3.6/site-packages/mastodon/Mastodon.py", line 1732, in __stream
    listener.handle_stream(r)
  File "/home/kiritan/.pyenv/versions/3.6.4/lib/python3.6/site-packages/mastodon/streaming.py", line 46, in handle_stream
    for chunk in response.iter_content(chunk_size = 1):
  File "/home/kiritan/.pyenv/versions/3.6.4/lib/python3.6/site-packages/requests/models.py", line 748, in generate
    raise ChunkedEncodingError(e)
requests.exceptions.ChunkedEncodingError: ('Connection broken: IncompleteRead(0 bytes read)', IncompleteRead(0 bytes read))

####2018/02/20 22:57:09####
Traceback (most recent call last):
  File "/home/kiritan/.pyenv/versions/3.6.4/lib/python3.6/site-packages/urllib3/response.py", line 543, in _update_chunk_length
    self.chunk_left = int(line, 16)
ValueError: invalid literal for int() with base 16: b''

During handling of the above exception, another exception occurred:

Traceback (most recent call last):
  File "/home/kiritan/.pyenv/versions/3.6.4/lib/python3.6/site-packages/urllib3/response.py", line 302, in _error_catcher
    yield
  File "/home/kiritan/.pyenv/versions/3.6.4/lib/python3.6/site-packages/urllib3/response.py", line 598, in read_chunked
    self._update_chunk_length()
  File "/home/kiritan/.pyenv/versions/3.6.4/lib/python3.6/site-packages/urllib3/response.py", line 547, in _update_chunk_length
    raise httplib.IncompleteRead(line)
http.client.IncompleteRead: IncompleteRead(0 bytes read)

During handling of the above exception, another exception occurred:

Traceback (most recent call last):
  File "/home/kiritan/.pyenv/versions/3.6.4/lib/python3.6/site-packages/requests/models.py", line 745, in generate
    for chunk in self.raw.stream(chunk_size, decode_content=True):
  File "/home/kiritan/.pyenv/versions/3.6.4/lib/python3.6/site-packages/urllib3/response.py", line 432, in stream
    for line in self.read_chunked(amt, decode_content=decode_content):
  File "/home/kiritan/.pyenv/versions/3.6.4/lib/python3.6/site-packages/urllib3/response.py", line 626, in read_chunked
    self._original_response.close()
  File "/home/kiritan/.pyenv/versions/3.6.4/lib/python3.6/contextlib.py", line 99, in __exit__
    self.gen.throw(type, value, traceback)
  File "/home/kiritan/.pyenv/versions/3.6.4/lib/python3.6/site-packages/urllib3/response.py", line 320, in _error_catcher
    raise ProtocolError('Connection broken: %r' % e, e)
urllib3.exceptions.ProtocolError: ('Connection broken: IncompleteRead(0 bytes read)', IncompleteRead(0 bytes read))

During handling of the above exception, another exception occurred:

Traceback (most recent call last):
  File "kiri_main.py", line 911, in t_user
    mastodon.stream_user(men_toot())
  File "<decorator-gen-65>", line 2, in stream_user
  File "/home/kiritan/.pyenv/versions/3.6.4/lib/python3.6/site-packages/mastodon/Mastodon.py", line 57, in wrapper
    return function(self, *args, **kwargs)
  File "/home/kiritan/.pyenv/versions/3.6.4/lib/python3.6/site-packages/mastodon/Mastodon.py", line 1391, in stream_user
    return self.__stream('/api/v1/streaming/user', listener, async=async)
  File "/home/kiritan/.pyenv/versions/3.6.4/lib/python3.6/site-packages/mastodon/Mastodon.py", line 1732, in __stream
    listener.handle_stream(r)
  File "/home/kiritan/.pyenv/versions/3.6.4/lib/python3.6/site-packages/mastodon/streaming.py", line 46, in handle_stream
    for chunk in response.iter_content(chunk_size = 1):
  File "/home/kiritan/.pyenv/versions/3.6.4/lib/python3.6/site-packages/requests/models.py", line 748, in generate
    raise ChunkedEncodingError(e)
requests.exceptions.ChunkedEncodingError: ('Connection broken: IncompleteRead(0 bytes read)', IncompleteRead(0 bytes read))

####2018/02/20 23:12:36####
Traceback (most recent call last):
  File "/home/kiritan/.pyenv/versions/3.6.4/lib/python3.6/site-packages/urllib3/response.py", line 543, in _update_chunk_length
    self.chunk_left = int(line, 16)
ValueError: invalid literal for int() with base 16: b''

During handling of the above exception, another exception occurred:

Traceback (most recent call last):
  File "/home/kiritan/.pyenv/versions/3.6.4/lib/python3.6/site-packages/urllib3/response.py", line 302, in _error_catcher
    yield
  File "/home/kiritan/.pyenv/versions/3.6.4/lib/python3.6/site-packages/urllib3/response.py", line 598, in read_chunked
    self._update_chunk_length()
  File "/home/kiritan/.pyenv/versions/3.6.4/lib/python3.6/site-packages/urllib3/response.py", line 547, in _update_chunk_length
    raise httplib.IncompleteRead(line)
http.client.IncompleteRead: IncompleteRead(0 bytes read)

During handling of the above exception, another exception occurred:

Traceback (most recent call last):
  File "/home/kiritan/.pyenv/versions/3.6.4/lib/python3.6/site-packages/requests/models.py", line 745, in generate
    for chunk in self.raw.stream(chunk_size, decode_content=True):
  File "/home/kiritan/.pyenv/versions/3.6.4/lib/python3.6/site-packages/urllib3/response.py", line 432, in stream
    for line in self.read_chunked(amt, decode_content=decode_content):
  File "/home/kiritan/.pyenv/versions/3.6.4/lib/python3.6/site-packages/urllib3/response.py", line 626, in read_chunked
    self._original_response.close()
  File "/home/kiritan/.pyenv/versions/3.6.4/lib/python3.6/contextlib.py", line 99, in __exit__
    self.gen.throw(type, value, traceback)
  File "/home/kiritan/.pyenv/versions/3.6.4/lib/python3.6/site-packages/urllib3/response.py", line 320, in _error_catcher
    raise ProtocolError('Connection broken: %r' % e, e)
urllib3.exceptions.ProtocolError: ('Connection broken: IncompleteRead(0 bytes read)', IncompleteRead(0 bytes read))

During handling of the above exception, another exception occurred:

Traceback (most recent call last):
  File "kiri_main.py", line 902, in t_local
    mastodon.stream_public(res_toot())
  File "<decorator-gen-66>", line 2, in stream_public
  File "/home/kiritan/.pyenv/versions/3.6.4/lib/python3.6/site-packages/mastodon/Mastodon.py", line 57, in wrapper
    return function(self, *args, **kwargs)
  File "/home/kiritan/.pyenv/versions/3.6.4/lib/python3.6/site-packages/mastodon/Mastodon.py", line 1398, in stream_public
    return self.__stream('/api/v1/streaming/public', listener, async=async)
  File "/home/kiritan/.pyenv/versions/3.6.4/lib/python3.6/site-packages/mastodon/Mastodon.py", line 1732, in __stream
    listener.handle_stream(r)
  File "/home/kiritan/.pyenv/versions/3.6.4/lib/python3.6/site-packages/mastodon/streaming.py", line 46, in handle_stream
    for chunk in response.iter_content(chunk_size = 1):
  File "/home/kiritan/.pyenv/versions/3.6.4/lib/python3.6/site-packages/requests/models.py", line 748, in generate
    raise ChunkedEncodingError(e)
requests.exceptions.ChunkedEncodingError: ('Connection broken: IncompleteRead(0 bytes read)', IncompleteRead(0 bytes read))

During handling of the above exception, another exception occurred:

Traceback (most recent call last):
  File "/home/kiritan/.pyenv/versions/3.6.4/lib/python3.6/site-packages/urllib3/response.py", line 543, in _update_chunk_length
    self.chunk_left = int(line, 16)
ValueError: invalid literal for int() with base 16: b''

During handling of the above exception, another exception occurred:

Traceback (most recent call last):
  File "/home/kiritan/.pyenv/versions/3.6.4/lib/python3.6/site-packages/urllib3/response.py", line 302, in _error_catcher
    yield
  File "/home/kiritan/.pyenv/versions/3.6.4/lib/python3.6/site-packages/urllib3/response.py", line 598, in read_chunked
    self._update_chunk_length()
  File "/home/kiritan/.pyenv/versions/3.6.4/lib/python3.6/site-packages/urllib3/response.py", line 547, in _update_chunk_length
    raise httplib.IncompleteRead(line)
http.client.IncompleteRead: IncompleteRead(0 bytes read)

During handling of the above exception, another exception occurred:

Traceback (most recent call last):
  File "/home/kiritan/.pyenv/versions/3.6.4/lib/python3.6/site-packages/requests/models.py", line 745, in generate
    for chunk in self.raw.stream(chunk_size, decode_content=True):
  File "/home/kiritan/.pyenv/versions/3.6.4/lib/python3.6/site-packages/urllib3/response.py", line 432, in stream
    for line in self.read_chunked(amt, decode_content=decode_content):
  File "/home/kiritan/.pyenv/versions/3.6.4/lib/python3.6/site-packages/urllib3/response.py", line 626, in read_chunked
    self._original_response.close()
  File "/home/kiritan/.pyenv/versions/3.6.4/lib/python3.6/contextlib.py", line 99, in __exit__
    self.gen.throw(type, value, traceback)
  File "/home/kiritan/.pyenv/versions/3.6.4/lib/python3.6/site-packages/urllib3/response.py", line 320, in _error_catcher
    raise ProtocolError('Connection broken: %r' % e, e)
urllib3.exceptions.ProtocolError: ('Connection broken: IncompleteRead(0 bytes read)', IncompleteRead(0 bytes read))

During handling of the above exception, another exception occurred:

Traceback (most recent call last):
  File "kiri_main.py", line 902, in t_local
    mastodon.stream_public(res_toot())
  File "<decorator-gen-66>", line 2, in stream_public
  File "/home/kiritan/.pyenv/versions/3.6.4/lib/python3.6/site-packages/mastodon/Mastodon.py", line 57, in wrapper
    return function(self, *args, **kwargs)
  File "/home/kiritan/.pyenv/versions/3.6.4/lib/python3.6/site-packages/mastodon/Mastodon.py", line 1398, in stream_public
    return self.__stream('/api/v1/streaming/public', listener, async=async)
  File "/home/kiritan/.pyenv/versions/3.6.4/lib/python3.6/site-packages/mastodon/Mastodon.py", line 1732, in __stream
    listener.handle_stream(r)
  File "/home/kiritan/.pyenv/versions/3.6.4/lib/python3.6/site-packages/mastodon/streaming.py", line 46, in handle_stream
    for chunk in response.iter_content(chunk_size = 1):
  File "/home/kiritan/.pyenv/versions/3.6.4/lib/python3.6/site-packages/requests/models.py", line 748, in generate
    raise ChunkedEncodingError(e)
requests.exceptions.ChunkedEncodingError: ('Connection broken: IncompleteRead(0 bytes read)', IncompleteRead(0 bytes read))

####2018/02/20 23:13:17####
Traceback (most recent call last):
  File "/home/kiritan/.pyenv/versions/3.6.4/lib/python3.6/site-packages/urllib3/response.py", line 543, in _update_chunk_length
    self.chunk_left = int(line, 16)
ValueError: invalid literal for int() with base 16: b''

During handling of the above exception, another exception occurred:

Traceback (most recent call last):
  File "/home/kiritan/.pyenv/versions/3.6.4/lib/python3.6/site-packages/urllib3/response.py", line 302, in _error_catcher
    yield
  File "/home/kiritan/.pyenv/versions/3.6.4/lib/python3.6/site-packages/urllib3/response.py", line 598, in read_chunked
    self._update_chunk_length()
  File "/home/kiritan/.pyenv/versions/3.6.4/lib/python3.6/site-packages/urllib3/response.py", line 547, in _update_chunk_length
    raise httplib.IncompleteRead(line)
http.client.IncompleteRead: IncompleteRead(0 bytes read)

During handling of the above exception, another exception occurred:

Traceback (most recent call last):
  File "/home/kiritan/.pyenv/versions/3.6.4/lib/python3.6/site-packages/requests/models.py", line 745, in generate
    for chunk in self.raw.stream(chunk_size, decode_content=True):
  File "/home/kiritan/.pyenv/versions/3.6.4/lib/python3.6/site-packages/urllib3/response.py", line 432, in stream
    for line in self.read_chunked(amt, decode_content=decode_content):
  File "/home/kiritan/.pyenv/versions/3.6.4/lib/python3.6/site-packages/urllib3/response.py", line 626, in read_chunked
    self._original_response.close()
  File "/home/kiritan/.pyenv/versions/3.6.4/lib/python3.6/contextlib.py", line 99, in __exit__
    self.gen.throw(type, value, traceback)
  File "/home/kiritan/.pyenv/versions/3.6.4/lib/python3.6/site-packages/urllib3/response.py", line 320, in _error_catcher
    raise ProtocolError('Connection broken: %r' % e, e)
urllib3.exceptions.ProtocolError: ('Connection broken: IncompleteRead(0 bytes read)', IncompleteRead(0 bytes read))

During handling of the above exception, another exception occurred:

Traceback (most recent call last):
  File "kiri_main.py", line 902, in t_local
    mastodon.stream_public(res_toot())
  File "<decorator-gen-66>", line 2, in stream_public
  File "/home/kiritan/.pyenv/versions/3.6.4/lib/python3.6/site-packages/mastodon/Mastodon.py", line 57, in wrapper
    return function(self, *args, **kwargs)
  File "/home/kiritan/.pyenv/versions/3.6.4/lib/python3.6/site-packages/mastodon/Mastodon.py", line 1398, in stream_public
    return self.__stream('/api/v1/streaming/public', listener, async=async)
  File "/home/kiritan/.pyenv/versions/3.6.4/lib/python3.6/site-packages/mastodon/Mastodon.py", line 1732, in __stream
    listener.handle_stream(r)
  File "/home/kiritan/.pyenv/versions/3.6.4/lib/python3.6/site-packages/mastodon/streaming.py", line 46, in handle_stream
    for chunk in response.iter_content(chunk_size = 1):
  File "/home/kiritan/.pyenv/versions/3.6.4/lib/python3.6/site-packages/requests/models.py", line 748, in generate
    raise ChunkedEncodingError(e)
requests.exceptions.ChunkedEncodingError: ('Connection broken: IncompleteRead(0 bytes read)', IncompleteRead(0 bytes read))

During handling of the above exception, another exception occurred:

Traceback (most recent call last):
  File "/home/kiritan/.pyenv/versions/3.6.4/lib/python3.6/site-packages/urllib3/response.py", line 543, in _update_chunk_length
    self.chunk_left = int(line, 16)
ValueError: invalid literal for int() with base 16: b''

During handling of the above exception, another exception occurred:

Traceback (most recent call last):
  File "/home/kiritan/.pyenv/versions/3.6.4/lib/python3.6/site-packages/urllib3/response.py", line 302, in _error_catcher
    yield
  File "/home/kiritan/.pyenv/versions/3.6.4/lib/python3.6/site-packages/urllib3/response.py", line 598, in read_chunked
    self._update_chunk_length()
  File "/home/kiritan/.pyenv/versions/3.6.4/lib/python3.6/site-packages/urllib3/response.py", line 547, in _update_chunk_length
    raise httplib.IncompleteRead(line)
http.client.IncompleteRead: IncompleteRead(0 bytes read)

During handling of the above exception, another exception occurred:

Traceback (most recent call last):
  File "/home/kiritan/.pyenv/versions/3.6.4/lib/python3.6/site-packages/requests/models.py", line 745, in generate
    for chunk in self.raw.stream(chunk_size, decode_content=True):
  File "/home/kiritan/.pyenv/versions/3.6.4/lib/python3.6/site-packages/urllib3/response.py", line 432, in stream
    for line in self.read_chunked(amt, decode_content=decode_content):
  File "/home/kiritan/.pyenv/versions/3.6.4/lib/python3.6/site-packages/urllib3/response.py", line 626, in read_chunked
    self._original_response.close()
  File "/home/kiritan/.pyenv/versions/3.6.4/lib/python3.6/contextlib.py", line 99, in __exit__
    self.gen.throw(type, value, traceback)
  File "/home/kiritan/.pyenv/versions/3.6.4/lib/python3.6/site-packages/urllib3/response.py", line 320, in _error_catcher
    raise ProtocolError('Connection broken: %r' % e, e)
urllib3.exceptions.ProtocolError: ('Connection broken: IncompleteRead(0 bytes read)', IncompleteRead(0 bytes read))

During handling of the above exception, another exception occurred:

Traceback (most recent call last):
  File "kiri_main.py", line 902, in t_local
    mastodon.stream_public(res_toot())
  File "<decorator-gen-66>", line 2, in stream_public
  File "/home/kiritan/.pyenv/versions/3.6.4/lib/python3.6/site-packages/mastodon/Mastodon.py", line 57, in wrapper
    return function(self, *args, **kwargs)
  File "/home/kiritan/.pyenv/versions/3.6.4/lib/python3.6/site-packages/mastodon/Mastodon.py", line 1398, in stream_public
    return self.__stream('/api/v1/streaming/public', listener, async=async)
  File "/home/kiritan/.pyenv/versions/3.6.4/lib/python3.6/site-packages/mastodon/Mastodon.py", line 1732, in __stream
    listener.handle_stream(r)
  File "/home/kiritan/.pyenv/versions/3.6.4/lib/python3.6/site-packages/mastodon/streaming.py", line 46, in handle_stream
    for chunk in response.iter_content(chunk_size = 1):
  File "/home/kiritan/.pyenv/versions/3.6.4/lib/python3.6/site-packages/requests/models.py", line 748, in generate
    raise ChunkedEncodingError(e)
requests.exceptions.ChunkedEncodingError: ('Connection broken: IncompleteRead(0 bytes read)', IncompleteRead(0 bytes read))

During handling of the above exception, another exception occurred:

Traceback (most recent call last):
  File "/home/kiritan/.pyenv/versions/3.6.4/lib/python3.6/site-packages/urllib3/response.py", line 543, in _update_chunk_length
    self.chunk_left = int(line, 16)
ValueError: invalid literal for int() with base 16: b''

During handling of the above exception, another exception occurred:

Traceback (most recent call last):
  File "/home/kiritan/.pyenv/versions/3.6.4/lib/python3.6/site-packages/urllib3/response.py", line 302, in _error_catcher
    yield
  File "/home/kiritan/.pyenv/versions/3.6.4/lib/python3.6/site-packages/urllib3/response.py", line 598, in read_chunked
    self._update_chunk_length()
  File "/home/kiritan/.pyenv/versions/3.6.4/lib/python3.6/site-packages/urllib3/response.py", line 547, in _update_chunk_length
    raise httplib.IncompleteRead(line)
http.client.IncompleteRead: IncompleteRead(0 bytes read)

During handling of the above exception, another exception occurred:

Traceback (most recent call last):
  File "/home/kiritan/.pyenv/versions/3.6.4/lib/python3.6/site-packages/requests/models.py", line 745, in generate
    for chunk in self.raw.stream(chunk_size, decode_content=True):
  File "/home/kiritan/.pyenv/versions/3.6.4/lib/python3.6/site-packages/urllib3/response.py", line 432, in stream
    for line in self.read_chunked(amt, decode_content=decode_content):
  File "/home/kiritan/.pyenv/versions/3.6.4/lib/python3.6/site-packages/urllib3/response.py", line 626, in read_chunked
    self._original_response.close()
  File "/home/kiritan/.pyenv/versions/3.6.4/lib/python3.6/contextlib.py", line 99, in __exit__
    self.gen.throw(type, value, traceback)
  File "/home/kiritan/.pyenv/versions/3.6.4/lib/python3.6/site-packages/urllib3/response.py", line 320, in _error_catcher
    raise ProtocolError('Connection broken: %r' % e, e)
urllib3.exceptions.ProtocolError: ('Connection broken: IncompleteRead(0 bytes read)', IncompleteRead(0 bytes read))

During handling of the above exception, another exception occurred:

Traceback (most recent call last):
  File "kiri_main.py", line 902, in t_local
    mastodon.stream_public(res_toot())
  File "<decorator-gen-66>", line 2, in stream_public
  File "/home/kiritan/.pyenv/versions/3.6.4/lib/python3.6/site-packages/mastodon/Mastodon.py", line 57, in wrapper
    return function(self, *args, **kwargs)
  File "/home/kiritan/.pyenv/versions/3.6.4/lib/python3.6/site-packages/mastodon/Mastodon.py", line 1398, in stream_public
    return self.__stream('/api/v1/streaming/public', listener, async=async)
  File "/home/kiritan/.pyenv/versions/3.6.4/lib/python3.6/site-packages/mastodon/Mastodon.py", line 1732, in __stream
    listener.handle_stream(r)
  File "/home/kiritan/.pyenv/versions/3.6.4/lib/python3.6/site-packages/mastodon/streaming.py", line 46, in handle_stream
    for chunk in response.iter_content(chunk_size = 1):
  File "/home/kiritan/.pyenv/versions/3.6.4/lib/python3.6/site-packages/requests/models.py", line 748, in generate
    raise ChunkedEncodingError(e)
requests.exceptions.ChunkedEncodingError: ('Connection broken: IncompleteRead(0 bytes read)', IncompleteRead(0 bytes read))

####2018/02/20 23:13:17####
Traceback (most recent call last):
  File "/home/kiritan/.pyenv/versions/3.6.4/lib/python3.6/site-packages/urllib3/response.py", line 543, in _update_chunk_length
    self.chunk_left = int(line, 16)
ValueError: invalid literal for int() with base 16: b''

During handling of the above exception, another exception occurred:

Traceback (most recent call last):
  File "/home/kiritan/.pyenv/versions/3.6.4/lib/python3.6/site-packages/urllib3/response.py", line 302, in _error_catcher
    yield
  File "/home/kiritan/.pyenv/versions/3.6.4/lib/python3.6/site-packages/urllib3/response.py", line 598, in read_chunked
    self._update_chunk_length()
  File "/home/kiritan/.pyenv/versions/3.6.4/lib/python3.6/site-packages/urllib3/response.py", line 547, in _update_chunk_length
    raise httplib.IncompleteRead(line)
http.client.IncompleteRead: IncompleteRead(0 bytes read)

During handling of the above exception, another exception occurred:

Traceback (most recent call last):
  File "/home/kiritan/.pyenv/versions/3.6.4/lib/python3.6/site-packages/requests/models.py", line 745, in generate
    for chunk in self.raw.stream(chunk_size, decode_content=True):
  File "/home/kiritan/.pyenv/versions/3.6.4/lib/python3.6/site-packages/urllib3/response.py", line 432, in stream
    for line in self.read_chunked(amt, decode_content=decode_content):
  File "/home/kiritan/.pyenv/versions/3.6.4/lib/python3.6/site-packages/urllib3/response.py", line 626, in read_chunked
    self._original_response.close()
  File "/home/kiritan/.pyenv/versions/3.6.4/lib/python3.6/contextlib.py", line 99, in __exit__
    self.gen.throw(type, value, traceback)
  File "/home/kiritan/.pyenv/versions/3.6.4/lib/python3.6/site-packages/urllib3/response.py", line 320, in _error_catcher
    raise ProtocolError('Connection broken: %r' % e, e)
urllib3.exceptions.ProtocolError: ('Connection broken: IncompleteRead(0 bytes read)', IncompleteRead(0 bytes read))

During handling of the above exception, another exception occurred:

Traceback (most recent call last):
  File "kiri_main.py", line 911, in t_user
    mastodon.stream_user(men_toot())
  File "<decorator-gen-65>", line 2, in stream_user
  File "/home/kiritan/.pyenv/versions/3.6.4/lib/python3.6/site-packages/mastodon/Mastodon.py", line 57, in wrapper
    return function(self, *args, **kwargs)
  File "/home/kiritan/.pyenv/versions/3.6.4/lib/python3.6/site-packages/mastodon/Mastodon.py", line 1391, in stream_user
    return self.__stream('/api/v1/streaming/user', listener, async=async)
  File "/home/kiritan/.pyenv/versions/3.6.4/lib/python3.6/site-packages/mastodon/Mastodon.py", line 1732, in __stream
    listener.handle_stream(r)
  File "/home/kiritan/.pyenv/versions/3.6.4/lib/python3.6/site-packages/mastodon/streaming.py", line 46, in handle_stream
    for chunk in response.iter_content(chunk_size = 1):
  File "/home/kiritan/.pyenv/versions/3.6.4/lib/python3.6/site-packages/requests/models.py", line 748, in generate
    raise ChunkedEncodingError(e)
requests.exceptions.ChunkedEncodingError: ('Connection broken: IncompleteRead(0 bytes read)', IncompleteRead(0 bytes read))

During handling of the above exception, another exception occurred:

Traceback (most recent call last):
  File "/home/kiritan/.pyenv/versions/3.6.4/lib/python3.6/site-packages/urllib3/response.py", line 543, in _update_chunk_length
    self.chunk_left = int(line, 16)
ValueError: invalid literal for int() with base 16: b''

During handling of the above exception, another exception occurred:

Traceback (most recent call last):
  File "/home/kiritan/.pyenv/versions/3.6.4/lib/python3.6/site-packages/urllib3/response.py", line 302, in _error_catcher
    yield
  File "/home/kiritan/.pyenv/versions/3.6.4/lib/python3.6/site-packages/urllib3/response.py", line 598, in read_chunked
    self._update_chunk_length()
  File "/home/kiritan/.pyenv/versions/3.6.4/lib/python3.6/site-packages/urllib3/response.py", line 547, in _update_chunk_length
    raise httplib.IncompleteRead(line)
http.client.IncompleteRead: IncompleteRead(0 bytes read)

During handling of the above exception, another exception occurred:

Traceback (most recent call last):
  File "/home/kiritan/.pyenv/versions/3.6.4/lib/python3.6/site-packages/requests/models.py", line 745, in generate
    for chunk in self.raw.stream(chunk_size, decode_content=True):
  File "/home/kiritan/.pyenv/versions/3.6.4/lib/python3.6/site-packages/urllib3/response.py", line 432, in stream
    for line in self.read_chunked(amt, decode_content=decode_content):
  File "/home/kiritan/.pyenv/versions/3.6.4/lib/python3.6/site-packages/urllib3/response.py", line 626, in read_chunked
    self._original_response.close()
  File "/home/kiritan/.pyenv/versions/3.6.4/lib/python3.6/contextlib.py", line 99, in __exit__
    self.gen.throw(type, value, traceback)
  File "/home/kiritan/.pyenv/versions/3.6.4/lib/python3.6/site-packages/urllib3/response.py", line 320, in _error_catcher
    raise ProtocolError('Connection broken: %r' % e, e)
urllib3.exceptions.ProtocolError: ('Connection broken: IncompleteRead(0 bytes read)', IncompleteRead(0 bytes read))

During handling of the above exception, another exception occurred:

Traceback (most recent call last):
  File "kiri_main.py", line 911, in t_user
    mastodon.stream_user(men_toot())
  File "<decorator-gen-65>", line 2, in stream_user
  File "/home/kiritan/.pyenv/versions/3.6.4/lib/python3.6/site-packages/mastodon/Mastodon.py", line 57, in wrapper
    return function(self, *args, **kwargs)
  File "/home/kiritan/.pyenv/versions/3.6.4/lib/python3.6/site-packages/mastodon/Mastodon.py", line 1391, in stream_user
    return self.__stream('/api/v1/streaming/user', listener, async=async)
  File "/home/kiritan/.pyenv/versions/3.6.4/lib/python3.6/site-packages/mastodon/Mastodon.py", line 1732, in __stream
    listener.handle_stream(r)
  File "/home/kiritan/.pyenv/versions/3.6.4/lib/python3.6/site-packages/mastodon/streaming.py", line 46, in handle_stream
    for chunk in response.iter_content(chunk_size = 1):
  File "/home/kiritan/.pyenv/versions/3.6.4/lib/python3.6/site-packages/requests/models.py", line 748, in generate
    raise ChunkedEncodingError(e)
requests.exceptions.ChunkedEncodingError: ('Connection broken: IncompleteRead(0 bytes read)', IncompleteRead(0 bytes read))
